08/02/22 (13:38:42) | ERROR: <urlopen error [Errno -3] Temporary failure in name resolution>
Traceback (most recent call last):
  File "/usr/lib/python3.10/urllib/request.py", line 1348, in do_open
    h.request(req.get_method(), req.selector, req.data, headers,
  File "/usr/lib/python3.10/http/client.py", line 1282, in request
    self._send_request(method, url, body, headers, encode_chunked)
  File "/usr/lib/python3.10/http/client.py", line 1328, in _send_request
    self.endheaders(body, encode_chunked=encode_chunked)
  File "/usr/lib/python3.10/http/client.py", line 1277, in endheaders
    self._send_output(message_body, encode_chunked=encode_chunked)
  File "/usr/lib/python3.10/http/client.py", line 1037, in _send_output
    self.send(msg)
  File "/usr/lib/python3.10/http/client.py", line 975, in send
    self.connect()
  File "/usr/lib/python3.10/http/client.py", line 1447, in connect
    super().connect()
  File "/usr/lib/python3.10/http/client.py", line 941, in connect
    self.sock = self._create_connection(
  File "/usr/lib/python3.10/socket.py", line 824, in create_connection
    for res in getaddrinfo(host, port, 0, SOCK_STREAM):
  File "/usr/lib/python3.10/socket.py", line 955, in getaddrinfo
    for res in _socket.getaddrinfo(host, port, family, type, proto, flags):
socket.gaierror: [Errno -3] Temporary failure in name resolution

During handling of the above exception, another exception occurred:

Traceback (most recent call last):
  File "/usr/bin/bpytop", line 5029, in _checker
    with urllib.request.urlopen("https://github.com/aristocratos/bpytop/raw/master/bpytop.py", timeout=5) as source: # type: ignore
  File "/usr/lib/python3.10/urllib/request.py", line 216, in urlopen
    return opener.open(url, data, timeout)
  File "/usr/lib/python3.10/urllib/request.py", line 519, in open
    response = self._open(req, data)
  File "/usr/lib/python3.10/urllib/request.py", line 536, in _open
    result = self._call_chain(self.handle_open, protocol, protocol +
  File "/usr/lib/python3.10/urllib/request.py", line 496, in _call_chain
    result = func(*args)
  File "/usr/lib/python3.10/urllib/request.py", line 1391, in https_open
    return self.do_open(http.client.HTTPSConnection, req,
  File "/usr/lib/python3.10/urllib/request.py", line 1351, in do_open
    raise URLError(err)
urllib.error.URLError: <urlopen error [Errno -3] Temporary failure in name resolution>
10/05/22 (11:44:34) | ERROR: <urlopen error [Errno -3] Temporary failure in name resolution>
Traceback (most recent call last):
  File "/usr/lib/python3.10/urllib/request.py", line 1348, in do_open
    h.request(req.get_method(), req.selector, req.data, headers,
  File "/usr/lib/python3.10/http/client.py", line 1282, in request
    self._send_request(method, url, body, headers, encode_chunked)
  File "/usr/lib/python3.10/http/client.py", line 1328, in _send_request
    self.endheaders(body, encode_chunked=encode_chunked)
  File "/usr/lib/python3.10/http/client.py", line 1277, in endheaders
    self._send_output(message_body, encode_chunked=encode_chunked)
  File "/usr/lib/python3.10/http/client.py", line 1037, in _send_output
    self.send(msg)
  File "/usr/lib/python3.10/http/client.py", line 975, in send
    self.connect()
  File "/usr/lib/python3.10/http/client.py", line 1447, in connect
    super().connect()
  File "/usr/lib/python3.10/http/client.py", line 941, in connect
    self.sock = self._create_connection(
  File "/usr/lib/python3.10/socket.py", line 824, in create_connection
    for res in getaddrinfo(host, port, 0, SOCK_STREAM):
  File "/usr/lib/python3.10/socket.py", line 955, in getaddrinfo
    for res in _socket.getaddrinfo(host, port, family, type, proto, flags):
socket.gaierror: [Errno -3] Temporary failure in name resolution

During handling of the above exception, another exception occurred:

Traceback (most recent call last):
  File "/usr/bin/bpytop", line 5029, in _checker
    with urllib.request.urlopen("https://github.com/aristocratos/bpytop/raw/master/bpytop.py", timeout=5) as source: # type: ignore
  File "/usr/lib/python3.10/urllib/request.py", line 216, in urlopen
    return opener.open(url, data, timeout)
  File "/usr/lib/python3.10/urllib/request.py", line 519, in open
    response = self._open(req, data)
  File "/usr/lib/python3.10/urllib/request.py", line 536, in _open
    result = self._call_chain(self.handle_open, protocol, protocol +
  File "/usr/lib/python3.10/urllib/request.py", line 496, in _call_chain
    result = func(*args)
  File "/usr/lib/python3.10/urllib/request.py", line 1391, in https_open
    return self.do_open(http.client.HTTPSConnection, req,
  File "/usr/lib/python3.10/urllib/request.py", line 1351, in do_open
    raise URLError(err)
urllib.error.URLError: <urlopen error [Errno -3] Temporary failure in name resolution>
03/06/22 (13:14:56) | WARNING: The menu system only works on a terminal size of 80x24 or above!
06/06/22 (09:57:34) | WARNING: The menu system only works on a terminal size of 80x24 or above!
06/06/22 (09:57:35) | WARNING: The menu system only works on a terminal size of 80x24 or above!
06/06/22 (09:57:40) | WARNING: The menu system only works on a terminal size of 80x24 or above!
06/06/22 (09:57:41) | WARNING: The menu system only works on a terminal size of 80x24 or above!
06/06/22 (09:57:41) | WARNING: The menu system only works on a terminal size of 80x24 or above!
06/06/22 (09:57:42) | WARNING: The menu system only works on a terminal size of 80x24 or above!
06/06/22 (09:57:51) | WARNING: The menu system only works on a terminal size of 80x24 or above!
06/06/22 (09:57:51) | WARNING: The menu system only works on a terminal size of 80x24 or above!
06/06/22 (09:57:52) | WARNING: The menu system only works on a terminal size of 80x24 or above!
06/06/22 (09:57:52) | WARNING: The menu system only works on a terminal size of 80x24 or above!
06/06/22 (09:57:56) | WARNING: The menu system only works on a terminal size of 80x24 or above!
06/06/22 (09:57:57) | WARNING: The menu system only works on a terminal size of 80x24 or above!
06/06/22 (09:57:57) | WARNING: The menu system only works on a terminal size of 80x24 or above!
06/06/22 (09:57:57) | WARNING: The menu system only works on a terminal size of 80x24 or above!
06/06/22 (09:57:57) | WARNING: The menu system only works on a terminal size of 80x24 or above!
06/06/22 (09:57:58) | WARNING: The menu system only works on a terminal size of 80x24 or above!
06/06/22 (09:57:58) | WARNING: The menu system only works on a terminal size of 80x24 or above!
06/06/22 (09:57:58) | WARNING: The menu system only works on a terminal size of 80x24 or above!
06/06/22 (09:57:58) | WARNING: The menu system only works on a terminal size of 80x24 or above!
06/06/22 (09:58:14) | WARNING: The menu system only works on a terminal size of 80x24 or above!
06/06/22 (09:58:15) | WARNING: The menu system only works on a terminal size of 80x24 or above!
06/06/22 (10:18:17) | WARNING: The menu system only works on a terminal size of 80x24 or above!
13/06/22 (18:35:45) | WARNING: The menu system only works on a terminal size of 80x24 or above!
13/06/22 (18:40:52) | WARNING: The menu system only works on a terminal size of 80x24 or above!
13/06/22 (18:40:53) | WARNING: The menu system only works on a terminal size of 80x24 or above!
13/06/22 (18:40:55) | WARNING: The menu system only works on a terminal size of 80x24 or above!
13/06/22 (18:40:56) | WARNING: The menu system only works on a terminal size of 80x24 or above!
13/06/22 (18:40:56) | WARNING: The menu system only works on a terminal size of 80x24 or above!
13/06/22 (18:40:57) | WARNING: The menu system only works on a terminal size of 80x24 or above!
13/06/22 (18:40:57) | WARNING: The menu system only works on a terminal size of 80x24 or above!
13/06/22 (18:40:57) | WARNING: The menu system only works on a terminal size of 80x24 or above!
13/06/22 (18:40:57) | WARNING: The menu system only works on a terminal size of 80x24 or above!
13/06/22 (18:41:02) | WARNING: The menu system only works on a terminal size of 80x24 or above!
13/06/22 (18:41:03) | WARNING: The menu system only works on a terminal size of 80x24 or above!
13/06/22 (18:41:04) | WARNING: The menu system only works on a terminal size of 80x24 or above!
13/06/22 (18:41:05) | WARNING: The menu system only works on a terminal size of 80x24 or above!
13/06/22 (18:41:06) | WARNING: The menu system only works on a terminal size of 80x24 or above!
26/06/22 (23:15:00) | ERROR: Exception when sending signal 9 to pid 3799
26/06/22 (23:15:00) | ERROR: [Errno 1] Operation not permitted
Traceback (most recent call last):
  File "/usr/bin/bpytop", line 5479, in process_keys
    os.kill(pid, sig)
PermissionError: [Errno 1] Operation not permitted
26/06/22 (23:15:06) | ERROR: Exception when sending signal 9 to pid 3799
26/06/22 (23:15:06) | ERROR: [Errno 1] Operation not permitted
Traceback (most recent call last):
  File "/usr/bin/bpytop", line 5479, in process_keys
    os.kill(pid, sig)
PermissionError: [Errno 1] Operation not permitted
26/06/22 (23:15:18) | ERROR: Exception when sending signal 9 to pid 3799
26/06/22 (23:15:18) | ERROR: [Errno 1] Operation not permitted
Traceback (most recent call last):
  File "/usr/bin/bpytop", line 5479, in process_keys
    os.kill(pid, sig)
PermissionError: [Errno 1] Operation not permitted
26/06/22 (23:15:21) | ERROR: Exception when sending signal 2 to pid 3799
26/06/22 (23:15:21) | ERROR: [Errno 1] Operation not permitted
Traceback (most recent call last):
  File "/usr/bin/bpytop", line 5479, in process_keys
    os.kill(pid, sig)
PermissionError: [Errno 1] Operation not permitted
26/06/22 (23:15:23) | ERROR: Exception when sending signal 15 to pid 3799
26/06/22 (23:15:23) | ERROR: [Errno 1] Operation not permitted
Traceback (most recent call last):
  File "/usr/bin/bpytop", line 5479, in process_keys
    os.kill(pid, sig)
PermissionError: [Errno 1] Operation not permitted
26/06/22 (23:15:26) | ERROR: Exception when sending signal 15 to pid 3799
26/06/22 (23:15:26) | ERROR: [Errno 1] Operation not permitted
Traceback (most recent call last):
  File "/usr/bin/bpytop", line 5479, in process_keys
    os.kill(pid, sig)
PermissionError: [Errno 1] Operation not permitted
26/06/22 (23:15:27) | ERROR: Exception when sending signal 9 to pid 3799
26/06/22 (23:15:27) | ERROR: [Errno 1] Operation not permitted
Traceback (most recent call last):
  File "/usr/bin/bpytop", line 5479, in process_keys
    os.kill(pid, sig)
PermissionError: [Errno 1] Operation not permitted
26/06/22 (23:15:40) | ERROR: Exception when sending signal 9 to pid 3799
26/06/22 (23:15:40) | ERROR: [Errno 1] Operation not permitted
Traceback (most recent call last):
  File "/usr/bin/bpytop", line 5479, in process_keys
    os.kill(pid, sig)
PermissionError: [Errno 1] Operation not permitted
26/06/22 (23:15:41) | ERROR: Exception when sending signal 9 to pid 3799
26/06/22 (23:15:41) | ERROR: [Errno 1] Operation not permitted
Traceback (most recent call last):
  File "/usr/bin/bpytop", line 5479, in process_keys
    os.kill(pid, sig)
PermissionError: [Errno 1] Operation not permitted
26/06/22 (23:15:41) | ERROR: Exception when sending signal 9 to pid 3799
26/06/22 (23:15:41) | ERROR: [Errno 1] Operation not permitted
Traceback (most recent call last):
  File "/usr/bin/bpytop", line 5479, in process_keys
    os.kill(pid, sig)
PermissionError: [Errno 1] Operation not permitted
26/06/22 (23:15:41) | ERROR: Exception when sending signal 9 to pid 3799
26/06/22 (23:15:41) | ERROR: [Errno 1] Operation not permitted
Traceback (most recent call last):
  File "/usr/bin/bpytop", line 5479, in process_keys
    os.kill(pid, sig)
PermissionError: [Errno 1] Operation not permitted
26/06/22 (23:15:41) | ERROR: Exception when sending signal 9 to pid 3799
26/06/22 (23:15:41) | ERROR: [Errno 1] Operation not permitted
Traceback (most recent call last):
  File "/usr/bin/bpytop", line 5479, in process_keys
    os.kill(pid, sig)
PermissionError: [Errno 1] Operation not permitted
26/06/22 (23:15:42) | ERROR: Exception when sending signal 9 to pid 3799
26/06/22 (23:15:42) | ERROR: [Errno 1] Operation not permitted
Traceback (most recent call last):
  File "/usr/bin/bpytop", line 5479, in process_keys
    os.kill(pid, sig)
PermissionError: [Errno 1] Operation not permitted
26/06/22 (23:15:42) | ERROR: Exception when sending signal 9 to pid 3799
26/06/22 (23:15:42) | ERROR: [Errno 1] Operation not permitted
Traceback (most recent call last):
  File "/usr/bin/bpytop", line 5479, in process_keys
    os.kill(pid, sig)
PermissionError: [Errno 1] Operation not permitted
26/06/22 (23:15:42) | ERROR: Exception when sending signal 9 to pid 3799
26/06/22 (23:15:42) | ERROR: [Errno 1] Operation not permitted
Traceback (most recent call last):
  File "/usr/bin/bpytop", line 5479, in process_keys
    os.kill(pid, sig)
PermissionError: [Errno 1] Operation not permitted
26/06/22 (23:15:42) | ERROR: Exception when sending signal 9 to pid 3799
26/06/22 (23:15:42) | ERROR: [Errno 1] Operation not permitted
Traceback (most recent call last):
  File "/usr/bin/bpytop", line 5479, in process_keys
    os.kill(pid, sig)
PermissionError: [Errno 1] Operation not permitted
26/06/22 (23:15:42) | ERROR: Exception when sending signal 9 to pid 3799
26/06/22 (23:15:42) | ERROR: [Errno 1] Operation not permitted
Traceback (most recent call last):
  File "/usr/bin/bpytop", line 5479, in process_keys
    os.kill(pid, sig)
PermissionError: [Errno 1] Operation not permitted
26/06/22 (23:15:42) | ERROR: Exception when sending signal 9 to pid 3799
26/06/22 (23:15:42) | ERROR: [Errno 1] Operation not permitted
Traceback (most recent call last):
  File "/usr/bin/bpytop", line 5479, in process_keys
    os.kill(pid, sig)
PermissionError: [Errno 1] Operation not permitted
26/06/22 (23:15:42) | ERROR: Exception when sending signal 9 to pid 3799
26/06/22 (23:15:42) | ERROR: [Errno 1] Operation not permitted
Traceback (most recent call last):
  File "/usr/bin/bpytop", line 5479, in process_keys
    os.kill(pid, sig)
PermissionError: [Errno 1] Operation not permitted
26/06/22 (23:15:43) | ERROR: Exception when sending signal 9 to pid 3799
26/06/22 (23:15:43) | ERROR: [Errno 1] Operation not permitted
Traceback (most recent call last):
  File "/usr/bin/bpytop", line 5479, in process_keys
    os.kill(pid, sig)
PermissionError: [Errno 1] Operation not permitted
26/06/22 (23:15:43) | ERROR: Exception when sending signal 9 to pid 3799
26/06/22 (23:15:43) | ERROR: [Errno 1] Operation not permitted
Traceback (most recent call last):
  File "/usr/bin/bpytop", line 5479, in process_keys
    os.kill(pid, sig)
PermissionError: [Errno 1] Operation not permitted
26/06/22 (23:15:43) | ERROR: Exception when sending signal 9 to pid 3799
26/06/22 (23:15:43) | ERROR: [Errno 1] Operation not permitted
Traceback (most recent call last):
  File "/usr/bin/bpytop", line 5479, in process_keys
    os.kill(pid, sig)
PermissionError: [Errno 1] Operation not permitted
26/06/22 (23:15:43) | ERROR: Exception when sending signal 9 to pid 3799
26/06/22 (23:15:43) | ERROR: [Errno 1] Operation not permitted
Traceback (most recent call last):
  File "/usr/bin/bpytop", line 5479, in process_keys
    os.kill(pid, sig)
PermissionError: [Errno 1] Operation not permitted
26/06/22 (23:15:43) | ERROR: Exception when sending signal 9 to pid 3799
26/06/22 (23:15:43) | ERROR: [Errno 1] Operation not permitted
Traceback (most recent call last):
  File "/usr/bin/bpytop", line 5479, in process_keys
    os.kill(pid, sig)
PermissionError: [Errno 1] Operation not permitted
26/06/22 (23:15:43) | ERROR: Exception when sending signal 9 to pid 3799
26/06/22 (23:15:43) | ERROR: [Errno 1] Operation not permitted
Traceback (most recent call last):
  File "/usr/bin/bpytop", line 5479, in process_keys
    os.kill(pid, sig)
PermissionError: [Errno 1] Operation not permitted
26/06/22 (23:15:44) | ERROR: Exception when sending signal 9 to pid 3799
26/06/22 (23:15:44) | ERROR: [Errno 1] Operation not permitted
Traceback (most recent call last):
  File "/usr/bin/bpytop", line 5479, in process_keys
    os.kill(pid, sig)
PermissionError: [Errno 1] Operation not permitted
26/06/22 (23:15:44) | ERROR: Exception when sending signal 15 to pid 3799
26/06/22 (23:15:44) | ERROR: [Errno 1] Operation not permitted
Traceback (most recent call last):
  File "/usr/bin/bpytop", line 5479, in process_keys
    os.kill(pid, sig)
PermissionError: [Errno 1] Operation not permitted
26/06/22 (23:15:44) | ERROR: Exception when sending signal 9 to pid 3799
26/06/22 (23:15:44) | ERROR: [Errno 1] Operation not permitted
Traceback (most recent call last):
  File "/usr/bin/bpytop", line 5479, in process_keys
    os.kill(pid, sig)
PermissionError: [Errno 1] Operation not permitted
26/06/22 (23:15:44) | ERROR: Exception when sending signal 15 to pid 3799
26/06/22 (23:15:44) | ERROR: [Errno 1] Operation not permitted
Traceback (most recent call last):
  File "/usr/bin/bpytop", line 5479, in process_keys
    os.kill(pid, sig)
PermissionError: [Errno 1] Operation not permitted
26/06/22 (23:15:44) | ERROR: Exception when sending signal 9 to pid 3799
26/06/22 (23:15:44) | ERROR: [Errno 1] Operation not permitted
Traceback (most recent call last):
  File "/usr/bin/bpytop", line 5479, in process_keys
    os.kill(pid, sig)
PermissionError: [Errno 1] Operation not permitted
26/06/22 (23:15:45) | ERROR: Exception when sending signal 15 to pid 3799
26/06/22 (23:15:45) | ERROR: [Errno 1] Operation not permitted
Traceback (most recent call last):
  File "/usr/bin/bpytop", line 5479, in process_keys
    os.kill(pid, sig)
PermissionError: [Errno 1] Operation not permitted
26/06/22 (23:15:45) | ERROR: Exception when sending signal 9 to pid 3799
26/06/22 (23:15:45) | ERROR: [Errno 1] Operation not permitted
Traceback (most recent call last):
  File "/usr/bin/bpytop", line 5479, in process_keys
    os.kill(pid, sig)
PermissionError: [Errno 1] Operation not permitted
26/06/22 (23:15:45) | ERROR: Exception when sending signal 15 to pid 3799
26/06/22 (23:15:45) | ERROR: [Errno 1] Operation not permitted
Traceback (most recent call last):
  File "/usr/bin/bpytop", line 5479, in process_keys
    os.kill(pid, sig)
PermissionError: [Errno 1] Operation not permitted
26/06/22 (23:15:45) | ERROR: Exception when sending signal 9 to pid 3799
26/06/22 (23:15:45) | ERROR: [Errno 1] Operation not permitted
Traceback (most recent call last):
  File "/usr/bin/bpytop", line 5479, in process_keys
    os.kill(pid, sig)
PermissionError: [Errno 1] Operation not permitted
26/06/22 (23:15:45) | ERROR: Exception when sending signal 15 to pid 3799
26/06/22 (23:15:45) | ERROR: [Errno 1] Operation not permitted
Traceback (most recent call last):
  File "/usr/bin/bpytop", line 5479, in process_keys
    os.kill(pid, sig)
PermissionError: [Errno 1] Operation not permitted
26/06/22 (23:15:45) | ERROR: Exception when sending signal 9 to pid 3799
26/06/22 (23:15:45) | ERROR: [Errno 1] Operation not permitted
Traceback (most recent call last):
  File "/usr/bin/bpytop", line 5479, in process_keys
    os.kill(pid, sig)
PermissionError: [Errno 1] Operation not permitted
26/06/22 (23:15:45) | ERROR: Exception when sending signal 15 to pid 3799
26/06/22 (23:15:45) | ERROR: [Errno 1] Operation not permitted
Traceback (most recent call last):
  File "/usr/bin/bpytop", line 5479, in process_keys
    os.kill(pid, sig)
PermissionError: [Errno 1] Operation not permitted
26/06/22 (23:15:45) | ERROR: Exception when sending signal 9 to pid 3799
26/06/22 (23:15:45) | ERROR: [Errno 1] Operation not permitted
Traceback (most recent call last):
  File "/usr/bin/bpytop", line 5479, in process_keys
    os.kill(pid, sig)
PermissionError: [Errno 1] Operation not permitted
26/06/22 (23:15:45) | ERROR: Exception when sending signal 15 to pid 3799
26/06/22 (23:15:45) | ERROR: [Errno 1] Operation not permitted
Traceback (most recent call last):
  File "/usr/bin/bpytop", line 5479, in process_keys
    os.kill(pid, sig)
PermissionError: [Errno 1] Operation not permitted
26/06/22 (23:15:45) | ERROR: Exception when sending signal 9 to pid 3799
26/06/22 (23:15:45) | ERROR: [Errno 1] Operation not permitted
Traceback (most recent call last):
  File "/usr/bin/bpytop", line 5479, in process_keys
    os.kill(pid, sig)
PermissionError: [Errno 1] Operation not permitted
26/06/22 (23:15:45) | ERROR: Exception when sending signal 9 to pid 3799
26/06/22 (23:15:45) | ERROR: [Errno 1] Operation not permitted
Traceback (most recent call last):
  File "/usr/bin/bpytop", line 5479, in process_keys
    os.kill(pid, sig)
PermissionError: [Errno 1] Operation not permitted
26/06/22 (23:15:45) | ERROR: Exception when sending signal 15 to pid 3799
26/06/22 (23:15:45) | ERROR: [Errno 1] Operation not permitted
Traceback (most recent call last):
  File "/usr/bin/bpytop", line 5479, in process_keys
    os.kill(pid, sig)
PermissionError: [Errno 1] Operation not permitted
26/06/22 (23:15:45) | ERROR: Exception when sending signal 9 to pid 3799
26/06/22 (23:15:45) | ERROR: [Errno 1] Operation not permitted
Traceback (most recent call last):
  File "/usr/bin/bpytop", line 5479, in process_keys
    os.kill(pid, sig)
PermissionError: [Errno 1] Operation not permitted
26/06/22 (23:15:46) | ERROR: Exception when sending signal 15 to pid 3799
26/06/22 (23:15:46) | ERROR: [Errno 1] Operation not permitted
Traceback (most recent call last):
  File "/usr/bin/bpytop", line 5479, in process_keys
    os.kill(pid, sig)
PermissionError: [Errno 1] Operation not permitted
26/06/22 (23:15:46) | ERROR: Exception when sending signal 9 to pid 3799
26/06/22 (23:15:46) | ERROR: [Errno 1] Operation not permitted
Traceback (most recent call last):
  File "/usr/bin/bpytop", line 5479, in process_keys
    os.kill(pid, sig)
PermissionError: [Errno 1] Operation not permitted
26/06/22 (23:15:46) | ERROR: Exception when sending signal 15 to pid 3799
26/06/22 (23:15:46) | ERROR: [Errno 1] Operation not permitted
Traceback (most recent call last):
  File "/usr/bin/bpytop", line 5479, in process_keys
    os.kill(pid, sig)
PermissionError: [Errno 1] Operation not permitted
26/06/22 (23:15:46) | ERROR: Exception when sending signal 9 to pid 3799
26/06/22 (23:15:46) | ERROR: [Errno 1] Operation not permitted
Traceback (most recent call last):
  File "/usr/bin/bpytop", line 5479, in process_keys
    os.kill(pid, sig)
PermissionError: [Errno 1] Operation not permitted
26/06/22 (23:15:46) | ERROR: Exception when sending signal 9 to pid 3799
26/06/22 (23:15:46) | ERROR: [Errno 1] Operation not permitted
Traceback (most recent call last):
  File "/usr/bin/bpytop", line 5479, in process_keys
    os.kill(pid, sig)
PermissionError: [Errno 1] Operation not permitted
26/06/22 (23:15:46) | ERROR: Exception when sending signal 15 to pid 3799
26/06/22 (23:15:46) | ERROR: [Errno 1] Operation not permitted
Traceback (most recent call last):
  File "/usr/bin/bpytop", line 5479, in process_keys
    os.kill(pid, sig)
PermissionError: [Errno 1] Operation not permitted
26/06/22 (23:15:46) | ERROR: Exception when sending signal 9 to pid 3799
26/06/22 (23:15:46) | ERROR: [Errno 1] Operation not permitted
Traceback (most recent call last):
  File "/usr/bin/bpytop", line 5479, in process_keys
    os.kill(pid, sig)
PermissionError: [Errno 1] Operation not permitted
26/06/22 (23:15:46) | ERROR: Exception when sending signal 15 to pid 3799
26/06/22 (23:15:46) | ERROR: [Errno 1] Operation not permitted
Traceback (most recent call last):
  File "/usr/bin/bpytop", line 5479, in process_keys
    os.kill(pid, sig)
PermissionError: [Errno 1] Operation not permitted
26/06/22 (23:15:46) | ERROR: Exception when sending signal 9 to pid 3799
26/06/22 (23:15:46) | ERROR: [Errno 1] Operation not permitted
Traceback (most recent call last):
  File "/usr/bin/bpytop", line 5479, in process_keys
    os.kill(pid, sig)
PermissionError: [Errno 1] Operation not permitted
26/06/22 (23:15:46) | ERROR: Exception when sending signal 9 to pid 3799
26/06/22 (23:15:46) | ERROR: [Errno 1] Operation not permitted
Traceback (most recent call last):
  File "/usr/bin/bpytop", line 5479, in process_keys
    os.kill(pid, sig)
PermissionError: [Errno 1] Operation not permitted
26/06/22 (23:15:46) | ERROR: Exception when sending signal 15 to pid 3799
26/06/22 (23:15:46) | ERROR: [Errno 1] Operation not permitted
Traceback (most recent call last):
  File "/usr/bin/bpytop", line 5479, in process_keys
    os.kill(pid, sig)
PermissionError: [Errno 1] Operation not permitted
26/06/22 (23:15:46) | ERROR: Exception when sending signal 9 to pid 3799
26/06/22 (23:15:46) | ERROR: [Errno 1] Operation not permitted
Traceback (most recent call last):
  File "/usr/bin/bpytop", line 5479, in process_keys
    os.kill(pid, sig)
PermissionError: [Errno 1] Operation not permitted
26/06/22 (23:17:33) | ERROR: Exception when sending signal 9 to pid 3799
26/06/22 (23:17:33) | ERROR: [Errno 1] Operation not permitted
Traceback (most recent call last):
  File "/usr/bin/bpytop", line 5479, in process_keys
    os.kill(pid, sig)
PermissionError: [Errno 1] Operation not permitted
26/06/22 (23:17:35) | ERROR: Exception when sending signal 9 to pid 8324
26/06/22 (23:17:35) | ERROR: [Errno 1] Operation not permitted
Traceback (most recent call last):
  File "/usr/bin/bpytop", line 5479, in process_keys
    os.kill(pid, sig)
PermissionError: [Errno 1] Operation not permitted
26/06/22 (23:17:38) | ERROR: Exception when sending signal 9 to pid 8324
26/06/22 (23:17:38) | ERROR: [Errno 1] Operation not permitted
Traceback (most recent call last):
  File "/usr/bin/bpytop", line 5479, in process_keys
    os.kill(pid, sig)
PermissionError: [Errno 1] Operation not permitted
26/06/22 (23:17:38) | ERROR: Exception when sending signal 9 to pid 8324
26/06/22 (23:17:38) | ERROR: [Errno 1] Operation not permitted
Traceback (most recent call last):
  File "/usr/bin/bpytop", line 5479, in process_keys
    os.kill(pid, sig)
PermissionError: [Errno 1] Operation not permitted
26/06/22 (23:17:38) | ERROR: Exception when sending signal 9 to pid 8324
26/06/22 (23:17:38) | ERROR: [Errno 1] Operation not permitted
Traceback (most recent call last):
  File "/usr/bin/bpytop", line 5479, in process_keys
    os.kill(pid, sig)
PermissionError: [Errno 1] Operation not permitted
26/06/22 (23:17:38) | ERROR: Exception when sending signal 9 to pid 8324
26/06/22 (23:17:38) | ERROR: [Errno 1] Operation not permitted
Traceback (most recent call last):
  File "/usr/bin/bpytop", line 5479, in process_keys
    os.kill(pid, sig)
PermissionError: [Errno 1] Operation not permitted
26/06/22 (23:17:39) | ERROR: Exception when sending signal 9 to pid 8324
26/06/22 (23:17:39) | ERROR: [Errno 1] Operation not permitted
Traceback (most recent call last):
  File "/usr/bin/bpytop", line 5479, in process_keys
    os.kill(pid, sig)
PermissionError: [Errno 1] Operation not permitted
26/06/22 (23:17:40) | ERROR: Exception when sending signal 9 to pid 3799
26/06/22 (23:17:40) | ERROR: [Errno 1] Operation not permitted
Traceback (most recent call last):
  File "/usr/bin/bpytop", line 5479, in process_keys
    os.kill(pid, sig)
PermissionError: [Errno 1] Operation not permitted
26/06/22 (23:17:40) | ERROR: Exception when sending signal 9 to pid 3799
26/06/22 (23:17:40) | ERROR: [Errno 1] Operation not permitted
Traceback (most recent call last):
  File "/usr/bin/bpytop", line 5479, in process_keys
    os.kill(pid, sig)
PermissionError: [Errno 1] Operation not permitted
26/06/22 (23:17:40) | ERROR: Exception when sending signal 9 to pid 3799
26/06/22 (23:17:40) | ERROR: [Errno 1] Operation not permitted
Traceback (most recent call last):
  File "/usr/bin/bpytop", line 5479, in process_keys
    os.kill(pid, sig)
PermissionError: [Errno 1] Operation not permitted
26/06/22 (23:17:40) | ERROR: Exception when sending signal 9 to pid 3799
26/06/22 (23:17:40) | ERROR: [Errno 1] Operation not permitted
Traceback (most recent call last):
  File "/usr/bin/bpytop", line 5479, in process_keys
    os.kill(pid, sig)
PermissionError: [Errno 1] Operation not permitted
26/06/22 (23:17:40) | ERROR: Exception when sending signal 9 to pid 3799
26/06/22 (23:17:40) | ERROR: [Errno 1] Operation not permitted
Traceback (most recent call last):
  File "/usr/bin/bpytop", line 5479, in process_keys
    os.kill(pid, sig)
PermissionError: [Errno 1] Operation not permitted
26/06/22 (23:17:42) | ERROR: Exception when sending signal 9 to pid 3799
26/06/22 (23:17:42) | ERROR: [Errno 1] Operation not permitted
Traceback (most recent call last):
  File "/usr/bin/bpytop", line 5479, in process_keys
    os.kill(pid, sig)
PermissionError: [Errno 1] Operation not permitted
26/06/22 (23:17:42) | ERROR: Exception when sending signal 9 to pid 3799
26/06/22 (23:17:42) | ERROR: [Errno 1] Operation not permitted
Traceback (most recent call last):
  File "/usr/bin/bpytop", line 5479, in process_keys
    os.kill(pid, sig)
PermissionError: [Errno 1] Operation not permitted
26/06/22 (23:17:42) | ERROR: Exception when sending signal 9 to pid 3799
26/06/22 (23:17:42) | ERROR: [Errno 1] Operation not permitted
Traceback (most recent call last):
  File "/usr/bin/bpytop", line 5479, in process_keys
    os.kill(pid, sig)
PermissionError: [Errno 1] Operation not permitted
26/06/22 (23:17:42) | ERROR: Exception when sending signal 9 to pid 3799
26/06/22 (23:17:42) | ERROR: [Errno 1] Operation not permitted
Traceback (most recent call last):
  File "/usr/bin/bpytop", line 5479, in process_keys
    os.kill(pid, sig)
PermissionError: [Errno 1] Operation not permitted
26/06/22 (23:17:42) | ERROR: Exception when sending signal 9 to pid 3799
26/06/22 (23:17:42) | ERROR: [Errno 1] Operation not permitted
Traceback (most recent call last):
  File "/usr/bin/bpytop", line 5479, in process_keys
    os.kill(pid, sig)
PermissionError: [Errno 1] Operation not permitted
26/06/22 (23:17:42) | ERROR: Exception when sending signal 9 to pid 3799
26/06/22 (23:17:42) | ERROR: [Errno 1] Operation not permitted
Traceback (most recent call last):
  File "/usr/bin/bpytop", line 5479, in process_keys
    os.kill(pid, sig)
PermissionError: [Errno 1] Operation not permitted
26/06/22 (23:17:43) | ERROR: Exception when sending signal 9 to pid 3799
26/06/22 (23:17:43) | ERROR: [Errno 1] Operation not permitted
Traceback (most recent call last):
  File "/usr/bin/bpytop", line 5479, in process_keys
    os.kill(pid, sig)
PermissionError: [Errno 1] Operation not permitted
11/09/22 (14:30:53) | ERROR: Input thread failed with exception: (5, 'Input/output error')
Traceback (most recent call last):
  File "/usr/bin/bpytop", line 954, in _get_key
    with Raw(sys.stdin):
  File "/usr/bin/bpytop", line 798, in __exit__
    termios.tcsetattr(self.stream, termios.TCSANOW, self.original_stty)
termios.error: (5, 'Input/output error')
16/09/22 (15:17:19) | WARNING: The menu system only works on a terminal size of 80x24 or above!
24/09/22 (11:46:56) | WARNING: The menu system only works on a terminal size of 80x24 or above!
07/11/22 (15:27:40) | ERROR: Exception when sending signal 9 to pid 16517
07/11/22 (15:27:40) | ERROR: [Errno 1] Operation not permitted
Traceback (most recent call last):
  File "/usr/bin/bpytop", line 5479, in process_keys
    os.kill(pid, sig)
PermissionError: [Errno 1] Operation not permitted
07/11/22 (15:27:42) | ERROR: Exception when sending signal 9 to pid 16517
07/11/22 (15:27:42) | ERROR: [Errno 1] Operation not permitted
Traceback (most recent call last):
  File "/usr/bin/bpytop", line 5479, in process_keys
    os.kill(pid, sig)
PermissionError: [Errno 1] Operation not permitted
07/11/22 (15:27:44) | ERROR: Exception when sending signal 15 to pid 16517
07/11/22 (15:27:44) | ERROR: [Errno 1] Operation not permitted
Traceback (most recent call last):
  File "/usr/bin/bpytop", line 5479, in process_keys
    os.kill(pid, sig)
PermissionError: [Errno 1] Operation not permitted
07/11/22 (15:27:47) | ERROR: Exception when sending signal 15 to pid 16517
07/11/22 (15:27:47) | ERROR: [Errno 1] Operation not permitted
Traceback (most recent call last):
  File "/usr/bin/bpytop", line 5479, in process_keys
    os.kill(pid, sig)
PermissionError: [Errno 1] Operation not permitted
07/11/22 (15:27:48) | ERROR: Exception when sending signal 9 to pid 16517
07/11/22 (15:27:48) | ERROR: [Errno 1] Operation not permitted
Traceback (most recent call last):
  File "/usr/bin/bpytop", line 5479, in process_keys
    os.kill(pid, sig)
PermissionError: [Errno 1] Operation not permitted
07/11/22 (15:27:49) | ERROR: Exception when sending signal 9 to pid 16517
07/11/22 (15:27:49) | ERROR: [Errno 1] Operation not permitted
Traceback (most recent call last):
  File "/usr/bin/bpytop", line 5479, in process_keys
    os.kill(pid, sig)
PermissionError: [Errno 1] Operation not permitted
07/11/22 (15:27:49) | ERROR: Exception when sending signal 9 to pid 16517
07/11/22 (15:27:49) | ERROR: [Errno 1] Operation not permitted
Traceback (most recent call last):
  File "/usr/bin/bpytop", line 5479, in process_keys
    os.kill(pid, sig)
PermissionError: [Errno 1] Operation not permitted
07/11/22 (15:27:49) | ERROR: Exception when sending signal 9 to pid 16517
07/11/22 (15:27:49) | ERROR: [Errno 1] Operation not permitted
Traceback (most recent call last):
  File "/usr/bin/bpytop", line 5479, in process_keys
    os.kill(pid, sig)
PermissionError: [Errno 1] Operation not permitted
07/11/22 (15:27:49) | ERROR: Exception when sending signal 9 to pid 16517
07/11/22 (15:27:49) | ERROR: [Errno 1] Operation not permitted
Traceback (most recent call last):
  File "/usr/bin/bpytop", line 5479, in process_keys
    os.kill(pid, sig)
PermissionError: [Errno 1] Operation not permitted
07/11/22 (15:27:55) | ERROR: Exception when sending signal 9 to pid 16517
07/11/22 (15:27:55) | ERROR: [Errno 1] Operation not permitted
Traceback (most recent call last):
  File "/usr/bin/bpytop", line 5479, in process_keys
    os.kill(pid, sig)
PermissionError: [Errno 1] Operation not permitted
07/11/22 (15:27:56) | ERROR: Exception when sending signal 2 to pid 16517
07/11/22 (15:27:56) | ERROR: [Errno 1] Operation not permitted
Traceback (most recent call last):
  File "/usr/bin/bpytop", line 5479, in process_keys
    os.kill(pid, sig)
PermissionError: [Errno 1] Operation not permitted
07/11/22 (15:27:57) | ERROR: Exception when sending signal 9 to pid 16517
07/11/22 (15:27:57) | ERROR: [Errno 1] Operation not permitted
Traceback (most recent call last):
  File "/usr/bin/bpytop", line 5479, in process_keys
    os.kill(pid, sig)
PermissionError: [Errno 1] Operation not permitted
08/11/22 (11:58:04) | ERROR: <urlopen error _ssl.c:980: The handshake operation timed out>
Traceback (most recent call last):
  File "/usr/lib/python3.10/urllib/request.py", line 1348, in do_open
    h.request(req.get_method(), req.selector, req.data, headers,
  File "/usr/lib/python3.10/http/client.py", line 1282, in request
    self._send_request(method, url, body, headers, encode_chunked)
  File "/usr/lib/python3.10/http/client.py", line 1328, in _send_request
    self.endheaders(body, encode_chunked=encode_chunked)
  File "/usr/lib/python3.10/http/client.py", line 1277, in endheaders
    self._send_output(message_body, encode_chunked=encode_chunked)
  File "/usr/lib/python3.10/http/client.py", line 1037, in _send_output
    self.send(msg)
  File "/usr/lib/python3.10/http/client.py", line 975, in send
    self.connect()
  File "/usr/lib/python3.10/http/client.py", line 1454, in connect
    self.sock = self._context.wrap_socket(self.sock,
  File "/usr/lib/python3.10/ssl.py", line 513, in wrap_socket
    return self.sslsocket_class._create(
  File "/usr/lib/python3.10/ssl.py", line 1071, in _create
    self.do_handshake()
  File "/usr/lib/python3.10/ssl.py", line 1342, in do_handshake
    self._sslobj.do_handshake()
TimeoutError: _ssl.c:980: The handshake operation timed out

During handling of the above exception, another exception occurred:

Traceback (most recent call last):
  File "/usr/bin/bpytop", line 5029, in _checker
    with urllib.request.urlopen("https://github.com/aristocratos/bpytop/raw/master/bpytop.py", timeout=5) as source: # type: ignore
  File "/usr/lib/python3.10/urllib/request.py", line 216, in urlopen
    return opener.open(url, data, timeout)
  File "/usr/lib/python3.10/urllib/request.py", line 519, in open
    response = self._open(req, data)
  File "/usr/lib/python3.10/urllib/request.py", line 536, in _open
    result = self._call_chain(self.handle_open, protocol, protocol +
  File "/usr/lib/python3.10/urllib/request.py", line 496, in _call_chain
    result = func(*args)
  File "/usr/lib/python3.10/urllib/request.py", line 1391, in https_open
    return self.do_open(http.client.HTTPSConnection, req,
  File "/usr/lib/python3.10/urllib/request.py", line 1351, in do_open
    raise URLError(err)
urllib.error.URLError: <urlopen error _ssl.c:980: The handshake operation timed out>
19/11/22 (18:55:29) | ERROR: Input thread failed with exception: (5, 'Input/output error')
Traceback (most recent call last):
  File "/usr/bin/bpytop", line 954, in _get_key
    with Raw(sys.stdin):
  File "/usr/bin/bpytop", line 798, in __exit__
    termios.tcsetattr(self.stream, termios.TCSANOW, self.original_stty)
termios.error: (5, 'Input/output error')
19/11/22 (19:08:23) | ERROR: Input thread failed with exception: (5, 'Input/output error')
Traceback (most recent call last):
  File "/usr/bin/bpytop", line 954, in _get_key
    with Raw(sys.stdin):
  File "/usr/bin/bpytop", line 798, in __exit__
    termios.tcsetattr(self.stream, termios.TCSANOW, self.original_stty)
termios.error: (5, 'Input/output error')
20/11/22 (09:53:14) | ERROR: <urlopen error [Errno -3] Temporary failure in name resolution>
Traceback (most recent call last):
  File "/usr/lib/python3.10/urllib/request.py", line 1348, in do_open
    h.request(req.get_method(), req.selector, req.data, headers,
  File "/usr/lib/python3.10/http/client.py", line 1282, in request
    self._send_request(method, url, body, headers, encode_chunked)
  File "/usr/lib/python3.10/http/client.py", line 1328, in _send_request
    self.endheaders(body, encode_chunked=encode_chunked)
  File "/usr/lib/python3.10/http/client.py", line 1277, in endheaders
    self._send_output(message_body, encode_chunked=encode_chunked)
  File "/usr/lib/python3.10/http/client.py", line 1037, in _send_output
    self.send(msg)
  File "/usr/lib/python3.10/http/client.py", line 975, in send
    self.connect()
  File "/usr/lib/python3.10/http/client.py", line 1447, in connect
    super().connect()
  File "/usr/lib/python3.10/http/client.py", line 941, in connect
    self.sock = self._create_connection(
  File "/usr/lib/python3.10/socket.py", line 824, in create_connection
    for res in getaddrinfo(host, port, 0, SOCK_STREAM):
  File "/usr/lib/python3.10/socket.py", line 955, in getaddrinfo
    for res in _socket.getaddrinfo(host, port, family, type, proto, flags):
socket.gaierror: [Errno -3] Temporary failure in name resolution

During handling of the above exception, another exception occurred:

Traceback (most recent call last):
  File "/usr/bin/bpytop", line 5029, in _checker
    with urllib.request.urlopen("https://github.com/aristocratos/bpytop/raw/master/bpytop.py", timeout=5) as source: # type: ignore
  File "/usr/lib/python3.10/urllib/request.py", line 216, in urlopen
    return opener.open(url, data, timeout)
  File "/usr/lib/python3.10/urllib/request.py", line 519, in open
    response = self._open(req, data)
  File "/usr/lib/python3.10/urllib/request.py", line 536, in _open
    result = self._call_chain(self.handle_open, protocol, protocol +
  File "/usr/lib/python3.10/urllib/request.py", line 496, in _call_chain
    result = func(*args)
  File "/usr/lib/python3.10/urllib/request.py", line 1391, in https_open
    return self.do_open(http.client.HTTPSConnection, req,
  File "/usr/lib/python3.10/urllib/request.py", line 1351, in do_open
    raise URLError(err)
urllib.error.URLError: <urlopen error [Errno -3] Temporary failure in name resolution>
21/11/22 (00:54:45) | ERROR: Data collection thread failed with exception: list index out of range
Traceback (most recent call last):
  File "/usr/bin/bpytop", line 2959, in _runner
    collector._draw()
  File "/usr/bin/bpytop", line 3991, in _draw
    ProcBox._draw_fg()
  File "/usr/bin/bpytop", line 2835, in _draw_fg
    vals += [f'{THEME.gradient["proc_color" if val < 100 else "process"][val if val < 100 else val - 100]}']
IndexError: list index out of range
21/11/22 (00:54:45) | WARNING: Exiting with errorcode (1). Runtime 0:00:00 

21/11/22 (00:56:41) | ERROR: Data collection thread failed with exception: list index out of range
Traceback (most recent call last):
  File "/usr/bin/bpytop", line 2959, in _runner
    collector._draw()
  File "/usr/bin/bpytop", line 3991, in _draw
    ProcBox._draw_fg()
  File "/usr/bin/bpytop", line 2835, in _draw_fg
    vals += [f'{THEME.gradient["proc_color" if val < 100 else "process"][val if val < 100 else val - 100]}']
IndexError: list index out of range
21/11/22 (00:56:41) | WARNING: Exiting with errorcode (1). Runtime 0:00:00 

22/11/22 (17:13:21) | ERROR: Data collection thread failed with exception: list index out of range
Traceback (most recent call last):
  File "/usr/bin/bpytop", line 2959, in _runner
    collector._draw()
  File "/usr/bin/bpytop", line 3991, in _draw
    ProcBox._draw_fg()
  File "/usr/bin/bpytop", line 2835, in _draw_fg
    vals += [f'{THEME.gradient["proc_color" if val < 100 else "process"][val if val < 100 else val - 100]}']
IndexError: list index out of range
22/11/22 (17:13:21) | WARNING: Exiting with errorcode (1). Runtime 0:00:00 

22/11/22 (17:13:27) | ERROR: Data collection thread failed with exception: list index out of range
Traceback (most recent call last):
  File "/usr/bin/bpytop", line 2959, in _runner
    collector._draw()
  File "/usr/bin/bpytop", line 3991, in _draw
    ProcBox._draw_fg()
  File "/usr/bin/bpytop", line 2835, in _draw_fg
    vals += [f'{THEME.gradient["proc_color" if val < 100 else "process"][val if val < 100 else val - 100]}']
IndexError: list index out of range
22/11/22 (17:13:27) | WARNING: Exiting with errorcode (1). Runtime 0:00:00 

04/12/22 (17:33:08) | ERROR: Data collection thread failed with exception: list index out of range
Traceback (most recent call last):
  File "/usr/bin/bpytop", line 2959, in _runner
    collector._draw()
  File "/usr/bin/bpytop", line 3991, in _draw
    ProcBox._draw_fg()
  File "/usr/bin/bpytop", line 2835, in _draw_fg
    vals += [f'{THEME.gradient["proc_color" if val < 100 else "process"][val if val < 100 else val - 100]}']
IndexError: list index out of range
04/12/22 (17:33:08) | WARNING: Exiting with errorcode (1). Runtime 0:00:00 

07/12/22 (17:09:20) | ERROR: Input thread failed with exception: (5, 'Input/output error')
Traceback (most recent call last):
  File "/usr/bin/bpytop", line 954, in _get_key
    with Raw(sys.stdin):
  File "/usr/bin/bpytop", line 798, in __exit__
    termios.tcsetattr(self.stream, termios.TCSANOW, self.original_stty)
termios.error: (5, 'Input/output error')
14/12/22 (00:27:16) | ERROR: Data collection thread failed with exception: list index out of range
Traceback (most recent call last):
  File "/usr/bin/bpytop", line 2959, in _runner
    collector._draw()
  File "/usr/bin/bpytop", line 3991, in _draw
    ProcBox._draw_fg()
  File "/usr/bin/bpytop", line 2835, in _draw_fg
    vals += [f'{THEME.gradient["proc_color" if val < 100 else "process"][val if val < 100 else val - 100]}']
IndexError: list index out of range
14/12/22 (00:27:16) | WARNING: Exiting with errorcode (1). Runtime 0:00:00 

15/12/22 (15:45:45) | ERROR: <urlopen error [Errno -3] Temporary failure in name resolution>
Traceback (most recent call last):
  File "/usr/lib/python3.10/urllib/request.py", line 1348, in do_open
    h.request(req.get_method(), req.selector, req.data, headers,
  File "/usr/lib/python3.10/http/client.py", line 1282, in request
    self._send_request(method, url, body, headers, encode_chunked)
  File "/usr/lib/python3.10/http/client.py", line 1328, in _send_request
    self.endheaders(body, encode_chunked=encode_chunked)
  File "/usr/lib/python3.10/http/client.py", line 1277, in endheaders
    self._send_output(message_body, encode_chunked=encode_chunked)
  File "/usr/lib/python3.10/http/client.py", line 1037, in _send_output
    self.send(msg)
  File "/usr/lib/python3.10/http/client.py", line 975, in send
    self.connect()
  File "/usr/lib/python3.10/http/client.py", line 1447, in connect
    super().connect()
  File "/usr/lib/python3.10/http/client.py", line 941, in connect
    self.sock = self._create_connection(
  File "/usr/lib/python3.10/socket.py", line 824, in create_connection
    for res in getaddrinfo(host, port, 0, SOCK_STREAM):
  File "/usr/lib/python3.10/socket.py", line 955, in getaddrinfo
    for res in _socket.getaddrinfo(host, port, family, type, proto, flags):
socket.gaierror: [Errno -3] Temporary failure in name resolution

During handling of the above exception, another exception occurred:

Traceback (most recent call last):
  File "/usr/bin/bpytop", line 5029, in _checker
    with urllib.request.urlopen("https://github.com/aristocratos/bpytop/raw/master/bpytop.py", timeout=5) as source: # type: ignore
  File "/usr/lib/python3.10/urllib/request.py", line 216, in urlopen
    return opener.open(url, data, timeout)
  File "/usr/lib/python3.10/urllib/request.py", line 519, in open
    response = self._open(req, data)
  File "/usr/lib/python3.10/urllib/request.py", line 536, in _open
    result = self._call_chain(self.handle_open, protocol, protocol +
  File "/usr/lib/python3.10/urllib/request.py", line 496, in _call_chain
    result = func(*args)
  File "/usr/lib/python3.10/urllib/request.py", line 1391, in https_open
    return self.do_open(http.client.HTTPSConnection, req,
  File "/usr/lib/python3.10/urllib/request.py", line 1351, in do_open
    raise URLError(err)
urllib.error.URLError: <urlopen error [Errno -3] Temporary failure in name resolution>
08/06/23 (17:29:08) | ERROR: Data collection thread failed with exception: Precision not allowed in integer format specifier
Traceback (most recent call last):
  File "/usr/bin/bpytop", line 2959, in _runner
    collector._draw()
  File "/usr/bin/bpytop", line 3991, in _draw
    ProcBox._draw_fg()
  File "/usr/bin/bpytop", line 2771, in _draw_fg
    (f'{proc.details["threads"]:^{iw}.{iw2}}' if expand > 0 else "") + (f'{proc.details["nice"]:^{iw}.{iw2}}' if expand > 1 else "") +
                                                                        ^^^^^^^^^^^^^^^^^^^^^^^^^^^^^^^^^^^^^
ValueError: Precision not allowed in integer format specifier
08/06/23 (17:29:08) | WARNING: Exiting with errorcode (1). Runtime 0:28:04 

13/06/23 (12:24:35) | ERROR: Input thread failed with exception: (5, 'Input/output error')
Traceback (most recent call last):
  File "/usr/bin/bpytop", line 954, in _get_key
    with Raw(sys.stdin):
  File "/usr/bin/bpytop", line 798, in __exit__
    termios.tcsetattr(self.stream, termios.TCSANOW, self.original_stty)
termios.error: (5, 'Input/output error')
08/07/23 (12:17:24) | INFO: Loglevel set to INFO
22/08/23 (14:57:51) | ERROR: Exception when sending signal 15 to pid 1
22/08/23 (14:57:51) | ERROR: [Errno 1] Operation not permitted
Traceback (most recent call last):
  File "/usr/bin/bpytop", line 5479, in process_keys
    os.kill(pid, sig)
PermissionError: [Errno 1] Operation not permitted
28/10/23 (22:37:46) | ERROR: <urlopen error _ssl.c:989: The handshake operation timed out>
Traceback (most recent call last):
  File "/usr/lib/python3.11/urllib/request.py", line 1348, in do_open
    h.request(req.get_method(), req.selector, req.data, headers,
  File "/usr/lib/python3.11/http/client.py", line 1286, in request
    self._send_request(method, url, body, headers, encode_chunked)
  File "/usr/lib/python3.11/http/client.py", line 1332, in _send_request
    self.endheaders(body, encode_chunked=encode_chunked)
  File "/usr/lib/python3.11/http/client.py", line 1281, in endheaders
    self._send_output(message_body, encode_chunked=encode_chunked)
  File "/usr/lib/python3.11/http/client.py", line 1041, in _send_output
    self.send(msg)
  File "/usr/lib/python3.11/http/client.py", line 979, in send
    self.connect()
  File "/usr/lib/python3.11/http/client.py", line 1458, in connect
    self.sock = self._context.wrap_socket(self.sock,
                ^^^^^^^^^^^^^^^^^^^^^^^^^^^^^^^^^^^^
  File "/usr/lib/python3.11/ssl.py", line 517, in wrap_socket
    return self.sslsocket_class._create(
           ^^^^^^^^^^^^^^^^^^^^^^^^^^^^^
  File "/usr/lib/python3.11/ssl.py", line 1108, in _create
    self.do_handshake()
  File "/usr/lib/python3.11/ssl.py", line 1379, in do_handshake
    self._sslobj.do_handshake()
TimeoutError: _ssl.c:989: The handshake operation timed out

During handling of the above exception, another exception occurred:

Traceback (most recent call last):
  File "/usr/bin/bpytop", line 5029, in _checker
    with urllib.request.urlopen("https://github.com/aristocratos/bpytop/raw/master/bpytop.py", timeout=5) as source: # type: ignore
         ^^^^^^^^^^^^^^^^^^^^^^^^^^^^^^^^^^^^^^^^^^^^^^^^^^^^^^^^^^^^^^^^^^^^^^^^^^^^^^^^^^^^^^^^^^^^^^^^
  File "/usr/lib/python3.11/urllib/request.py", line 216, in urlopen
    return opener.open(url, data, timeout)
           ^^^^^^^^^^^^^^^^^^^^^^^^^^^^^^^
  File "/usr/lib/python3.11/urllib/request.py", line 519, in open
    response = self._open(req, data)
               ^^^^^^^^^^^^^^^^^^^^^
  File "/usr/lib/python3.11/urllib/request.py", line 536, in _open
    result = self._call_chain(self.handle_open, protocol, protocol +
             ^^^^^^^^^^^^^^^^^^^^^^^^^^^^^^^^^^^^^^^^^^^^^^^^^^^^^^^
  File "/usr/lib/python3.11/urllib/request.py", line 496, in _call_chain
    result = func(*args)
             ^^^^^^^^^^^
  File "/usr/lib/python3.11/urllib/request.py", line 1391, in https_open
    return self.do_open(http.client.HTTPSConnection, req,
           ^^^^^^^^^^^^^^^^^^^^^^^^^^^^^^^^^^^^^^^^^^^^^^
  File "/usr/lib/python3.11/urllib/request.py", line 1351, in do_open
    raise URLError(err)
urllib.error.URLError: <urlopen error _ssl.c:989: The handshake operation timed out>
03/11/23 (14:57:20) | ERROR: HTTP Error 404: Not Found
Traceback (most recent call last):
  File "/usr/bin/bpytop", line 5029, in _checker
    with urllib.request.urlopen("https://github.com/aristocratos/bpytop/raw/master/bpytop.py", timeout=5) as source: # type: ignore
         ^^^^^^^^^^^^^^^^^^^^^^^^^^^^^^^^^^^^^^^^^^^^^^^^^^^^^^^^^^^^^^^^^^^^^^^^^^^^^^^^^^^^^^^^^^^^^^^^
  File "/usr/lib/python3.11/urllib/request.py", line 216, in urlopen
    return opener.open(url, data, timeout)
           ^^^^^^^^^^^^^^^^^^^^^^^^^^^^^^^
  File "/usr/lib/python3.11/urllib/request.py", line 525, in open
    response = meth(req, response)
               ^^^^^^^^^^^^^^^^^^^
  File "/usr/lib/python3.11/urllib/request.py", line 634, in http_response
    response = self.parent.error(
               ^^^^^^^^^^^^^^^^^^
  File "/usr/lib/python3.11/urllib/request.py", line 563, in error
    return self._call_chain(*args)
           ^^^^^^^^^^^^^^^^^^^^^^^
  File "/usr/lib/python3.11/urllib/request.py", line 496, in _call_chain
    result = func(*args)
             ^^^^^^^^^^^
  File "/usr/lib/python3.11/urllib/request.py", line 643, in http_error_default
    raise HTTPError(req.full_url, code, msg, hdrs, fp)
urllib.error.HTTPError: HTTP Error 404: Not Found
03/11/23 (14:59:57) | ERROR: HTTP Error 404: Not Found
Traceback (most recent call last):
  File "/usr/bin/bpytop", line 5029, in _checker
    with urllib.request.urlopen("https://github.com/aristocratos/bpytop/raw/master/bpytop.py", timeout=5) as source: # type: ignore
         ^^^^^^^^^^^^^^^^^^^^^^^^^^^^^^^^^^^^^^^^^^^^^^^^^^^^^^^^^^^^^^^^^^^^^^^^^^^^^^^^^^^^^^^^^^^^^^^^
  File "/usr/lib/python3.11/urllib/request.py", line 216, in urlopen
    return opener.open(url, data, timeout)
           ^^^^^^^^^^^^^^^^^^^^^^^^^^^^^^^
  File "/usr/lib/python3.11/urllib/request.py", line 525, in open
    response = meth(req, response)
               ^^^^^^^^^^^^^^^^^^^
  File "/usr/lib/python3.11/urllib/request.py", line 634, in http_response
    response = self.parent.error(
               ^^^^^^^^^^^^^^^^^^
  File "/usr/lib/python3.11/urllib/request.py", line 563, in error
    return self._call_chain(*args)
           ^^^^^^^^^^^^^^^^^^^^^^^
  File "/usr/lib/python3.11/urllib/request.py", line 496, in _call_chain
    result = func(*args)
             ^^^^^^^^^^^
  File "/usr/lib/python3.11/urllib/request.py", line 643, in http_error_default
    raise HTTPError(req.full_url, code, msg, hdrs, fp)
urllib.error.HTTPError: HTTP Error 404: Not Found
